<?xml version="1.0" encoding="utf-8"?>
<!-- This URDF was automatically created by SolidWorks to URDF Exporter! Originally created by Stephen Brawner (brawner@gmail.com) 
     Commit Version: 1.6.0-4-g7f85cfe  Build Version: 1.6.7995.38578
     For more information, please see http://wiki.ros.org/sw_urdf_exporter -->
<robot
  name="whitepost_description">
  <link
    name="base_link">
    <inertial>
      <origin
        xyz="-0.0878871849556058 -0.24031436576645 -0.00262201895905863"
        rpy="0 0 0" />
      <mass
        value="1.44247098515789" />
      <inertia
        ixx="0.00190082650789974"
        ixy="-6.54115106336875E-08"
        ixz="0.000158122643415958"
        iyy="0.00430567343735884"
        iyz="2.13686604503896E-07"
        izz="0.00562547913875254" />
    </inertial>
    <visual>
      <origin
        xyz="0 0 0"
        rpy="0 0 0" />
      <geometry>
        <mesh
          filename="package://whitepost_description/meshes/base_link.STL" />
      </geometry>
      <material
        name="">
        <color
          rgba="0.752941176470588 0.752941176470588 0.752941176470588 1" />
      </material>
    </visual>
    <collision>
      <origin
        xyz="0 0 0"
        rpy="0 0 0" />
      <geometry>
        <mesh
          filename="package://whitepost_description/meshes/base_link.STL" />
      </geometry>
    </collision>
  </link>
  <link
    name="link1">
    <inertial>
      <origin
        xyz="0.00484822061340437 -0.000304970456229264 0.0270397107750235"
        rpy="0 0 0" />
      <mass
        value="0.620101924539931" />
      <inertia
        ixx="0.000629808311211551"
        ixy="-3.97484032471268E-07"
        ixz="-6.73553682915433E-06"
        iyy="0.000749454499612437"
        iyz="-3.05630027277703E-07"
        izz="0.000566325959412686" />
    </inertial>
    <visual>
      <origin
        xyz="0 0 0"
        rpy="0 0 0" />
      <geometry>
        <mesh
          filename="package://whitepost_description/meshes/link1.STL" />
      </geometry>
      <material
        name="">
        <color
          rgba="0.752941176470588 0.752941176470588 0.752941176470588 1" />
      </material>
    </visual>
    <collision>
      <origin
        xyz="0 0 0"
        rpy="0 0 0" />
      <geometry>
        <mesh
          filename="package://whitepost_description/meshes/link1.STL" />
      </geometry>
    </collision>
  </link>
  <joint
    name="joint1"
    type="revolute">
    <origin
      xyz="-0.0159462258519159 -0.240246042857508 0.0583181110479435"
      rpy="0 0 0" />
    <parent
      link="base_link" />
    <child
      link="link1" />
    <axis
      xyz="0 0 1" />
    <limit
      lower="0"
      upper="4.7124"
      effort="0"
      velocity="0" />
  </joint>
  <link
    name="link2">
    <inertial>
      <origin
        xyz="-0.202032273233566 -7.88730675378713E-06 0.0249467072303828"
        rpy="0 0 0" />
      <mass
        value="1.41800319923908" />
      <inertia
        ixx="0.000989886540311289"
        ixy="3.32247329437961E-08"
        ixz="1.61925579310198E-05"
        iyy="0.00307607710917419"
        iyz="7.07490230653188E-09"
        izz="0.00328805724019953" />
    </inertial>
    <visual>
      <origin
        xyz="0 0 0"
        rpy="0 0 0" />
      <geometry>
        <mesh
          filename="package://whitepost_description/meshes/link2.STL" />
      </geometry>
      <material
        name="">
        <color
          rgba="0.752941176470588 0.752941176470588 0.752941176470588 1" />
      </material>
    </visual>
    <collision>
      <origin
        xyz="0 0 0"
        rpy="0 0 0" />
      <geometry>
        <mesh
          filename="package://whitepost_description/meshes/link2.STL" />
      </geometry>
    </collision>
  </link>
  <joint
    name="joint2"
    type="revolute">
    <origin
      xyz="0.0734962258519162 -0.00550395714249205 0.0449999999999996"
      rpy="-1.5707963267949 0 1.5707963267949" />
    <parent
      link="link1" />
    <child
      link="link2" />
    <axis
      xyz="0 0 1" />
    <limit
      lower="0"
      upper="3.1416"
      effort="0"
      velocity="0" />
  </joint>
  <link
    name="link3">
    <inertial>
      <origin
        xyz="0.242960164877792 0.00012337188422766 -0.0147772951400764"
        rpy="0 0 0" />
      <mass
        value="0.403417641072483" />
      <inertia
        ixx="9.56456633191661E-05"
        ixy="2.78560622329879E-09"
        ixz="5.96872643894562E-06"
        iyy="0.00155136464997689"
        iyz="1.32956952847832E-08"
        izz="0.00154677260648561" />
    </inertial>
    <visual>
      <origin
        xyz="0 0 0"
        rpy="0 0 0" />
      <geometry>
        <mesh
          filename="package://whitepost_description/meshes/link3.STL" />
      </geometry>
      <material
        name="">
        <color
          rgba="0.752941176470588 0.752941176470588 0.752941176470588 1" />
      </material>
    </visual>
    <collision>
      <origin
        xyz="0 0 0"
        rpy="0 0 0" />
      <geometry>
        <mesh
          filename="package://whitepost_description/meshes/link3.STL" />
      </geometry>
    </collision>
  </link>
  <joint
    name="joint3"
    type="revolute">
    <origin
      xyz="-0.568892521556106 5.00000000043382E-05 0.0689962258519109"
      rpy="0 0 0" />
    <parent
      link="link2" />
    <child
      link="link3" />
    <axis
      xyz="0 0 1" />
    <limit
      lower="0.13963"
      upper="6.2832"
      effort="0"
      velocity="0" />
  </joint>
  <link
    name="link4">
    <inertial>
      <origin
        xyz="0.00202084562805582 -0.0593866706994491 -0.032860760958691"
        rpy="0 0 0" />
      <mass
        value="0.183902372152348" />
      <inertia
        ixx="0.000130007338632221"
        ixy="-1.89655484055181E-08"
        ixz="-1.37057325298404E-07"
        iyy="0.000125916800836315"
        iyz="2.32931330679035E-06"
        izz="5.92844110982551E-05" />
    </inertial>
    <visual>
      <origin
        xyz="0 0 0"
        rpy="0 0 0" />
      <geometry>
        <mesh
          filename="package://whitepost_description/meshes/link4.STL" />
      </geometry>
      <material
        name="">
        <color
          rgba="0.752941176470588 0.752941176470588 0.752941176470588 1" />
      </material>
    </visual>
    <collision>
      <origin
        xyz="0 0 0"
        rpy="0 0 0" />
      <geometry>
        <mesh
          filename="package://whitepost_description/meshes/link4.STL" />
      </geometry>
    </collision>
  </link>
  <joint
    name="joint4"
    type="revolute">
    <origin
      xyz="0.4895 0.0002 0.0167"
      rpy="0 0 0" />
    <parent
      link="link3" />
    <child
      link="link4" />
    <axis
      xyz="0 0 1" />
    <limit
      lower="0"
      upper="3.1416"
      effort="0"
      velocity="0" />
  </joint>
  <link
    name="link5">
    <inertial>
      <origin
        xyz="-0.0446032766046531 -0.000162708163776337 0.0244626761334014"
        rpy="0 0 0" />
      <mass
        value="0.0824040607022898" />
      <inertia
        ixx="4.34716313620653E-05"
        ixy="-1.10140855123914E-09"
        ixz="2.10979217176686E-06"
        iyy="6.84180432466642E-05"
        iyz="-3.77593897613679E-09"
        izz="3.64032876394254E-05" />
    </inertial>
    <visual>
      <origin
        xyz="0 0 0"
        rpy="0 0 0" />
      <geometry>
        <mesh
          filename="package://whitepost_description/meshes/link5.STL" />
      </geometry>
      <material
        name="">
        <color
          rgba="0.752941176470588 0.752941176470588 0.752941176470588 1" />
      </material>
    </visual>
    <collision>
      <origin
        xyz="0 0 0"
        rpy="0 0 0" />
      <geometry>
        <mesh
          filename="package://whitepost_description/meshes/link5.STL" />
      </geometry>
    </collision>
  </link>
  <joint
    name="joint5"
    type="revolute">
    <origin
      xyz="-0.0295999999999965 -0.0748000000000026 -0.0408000000000002"
      rpy="0 -1.5707963267949 3.14159265358979" />
    <parent
      link="link4" />
    <child
      link="link5" />
    <axis
      xyz="0 0 1" />
    <limit
      lower="0"
      upper="3.1416"
      effort="0"
      velocity="0" />
  </joint>
</robot>